WARNING: Could not find any nv files on this host!
Countries: ['US', 'MX']
updates: False
neighbors: False
Store after 100000 records
Compression ratio: 18
id_type: user_id
app: spfraib_sentiments
wait_in_sec: 600
/scratch/spf248/twitter_data_collection/data
/scratch/spf248/twitter_labor_market_flows/data
13082022_no_updates_no_neighbors
SLURM_JOB_ID : 23539610
SLURM_ARRAY_TASK_ID : 63
SLURM_ARRAY_TASK_COUNT : 73
Load and select users:
# users: 563503
Computing Time: 7 sec
<class 'pandas.core.frame.DataFrame'>
Int64Index: 563503 entries, 597802 to 2957214
Data columns (total 3 columns):
 #   Column         Non-Null Count   Dtype 
---  ------         --------------   ----- 
 0   user_id        563503 non-null  object
 1   country_short  563503 non-null  object
 2   tweet_id       0 non-null       object
dtypes: object(3)
memory usage: 17.2+ MB
# keys: 73
key file: /scratch/spf248/twitter_data_collection/data/../keys/v1/spfraib_sentiments-ollin.json
Country: US
Pull: full
# users: 496004

Traceback (most recent call last):
  File "./code/timeline_API.py", line 150, in pull_from_user_timeline_API_endpoint
    for status in cursor:
  File "/ext3/miniconda3/lib/python3.8/site-packages/tweepy/cursor.py", line 86, in __next__
    return self.next()
  File "/ext3/miniconda3/lib/python3.8/site-packages/tweepy/cursor.py", line 286, in next
    self.current_page = next(self.page_iterator)
  File "/ext3/miniconda3/lib/python3.8/site-packages/tweepy/cursor.py", line 86, in __next__
    return self.next()
  File "/ext3/miniconda3/lib/python3.8/site-packages/tweepy/cursor.py", line 167, in next
    data = self.method(max_id=self.max_id, parser=RawParser(), *self.args, **self.kwargs)
  File "/ext3/miniconda3/lib/python3.8/site-packages/tweepy/api.py", line 33, in wrapper
    return method(*args, **kwargs)
  File "/ext3/miniconda3/lib/python3.8/site-packages/tweepy/api.py", line 46, in wrapper
    return method(*args, **kwargs)
  File "/ext3/miniconda3/lib/python3.8/site-packages/tweepy/api.py", line 571, in user_timeline
    return self.request(
  File "/ext3/miniconda3/lib/python3.8/site-packages/tweepy/api.py", line 257, in request
    raise Unauthorized(resp)
tweepy.errors.Unauthorized: 401 Unauthorized
Not authorized.

During handling of the above exception, another exception occurred:

Traceback (most recent call last):
  File "./code/timeline_API.py", line 221, in <module>
    pull_and_store(country_short,pull_type)
  File "./code/timeline_API.py", line 176, in pull_and_store
    timeline, error = pull_from_user_timeline_API_endpoint(api,user_id,id_type,tweet_id)
  File "./code/timeline_API.py", line 152, in pull_from_user_timeline_API_endpoint
    except tweepy.error.TweepError as e:
AttributeError: module 'tweepy' has no attribute 'error'

real	10m8.278s
user	0m5.760s
sys	0m2.030s
